Workbook

Sheet Bang_Thiet_Ke_Ca_Kiem_Thu
A1: Test Case ID | B1: Test Case | C1: Test Data | D1: Expected Results | E1: Actual Results | F1: Pass/Fail | G1: Kỹ thuật | H1: Ưu tiên | I1: Loại | J1: Phụ trách | K1: Ngày chạy | L1: Bug ID | M1: Ghi chú / Evidence
A2: 1. Chức năng đăng ký tài khoản (Bảng 4.7)
A3: REG-01 | B3: Đăng ký với thông tin hợp lệ | C3: họ tên: Nguyen Van Test email: nhom17.test+reg01@gmail.com (chưa dùng) SĐT: 09xxxxxxxx mật khẩu: Test@12345 | D3: Tạo tài khoản thành công, chuyển sang trạng thái đã đăng nhập hoặc yêu cầu xác thực | E3: Chưa thực hiện | G3: EP | H3: H | I3: A+M | J3: Quân
A4: REG-02 | B4: Để trống toàn bộ các trường rồi gửi | C4: Tất cả các trường: [trống] | D4: Không gửi được; báo lỗi ở từng trường bắt buộc | E4: Chưa thực hiện | G4: EP | H4: H | I4: A | J4: Quân
A5: REG-03 | B5: Để trống từng trường bắt buộc | C5: Lần lượt để trống: họ tên / email-SĐT / mật khẩu; các trường còn lại hợp lệ (parametrize) | D5: Báo lỗi đúng trường bị bỏ trống | E5: Chưa thực hiện | G5: EP | H5: H | I5: A | J5: Quân
A6: REG-04 | B6: Email sai định dạng | C6: email: abc | abc@ | @gmail.com | a b@x.com | a@x (parametrize) | D6: Báo lỗi định dạng email, không tạo tài khoản | E6: Chưa thực hiện | G6: EP | H6: H | I6: A | J6: Quân
A7: REG-05 | B7: SĐT sai định dạng (*) | C7: SĐT: 09abc12345 | 090123456 (thiếu số) | 09012345678901 (thừa số) | 1234567890 (không bắt đầu bằng 0) (parametrize) | D7: Báo lỗi định dạng SĐT, không tạo tài khoản | E7: Chưa thực hiện | G7: EP, BVA | H7: H | I7: A | J7: Quân
A8: REG-06 | B8: Đăng ký bằng email đã tồn tại | C8: email: email của tài khoản đã tạo ở REG-01 | D8: Báo email đã được sử dụng | E8: Chưa thực hiện | G8: EP | H8: H | I8: A+M | J8: Quân
A9: REG-07 | B9: Đăng ký bằng SĐT đã tồn tại | C9: SĐT: SĐT của tài khoản test có sẵn | D9: Báo SĐT đã được sử dụng | E9: Chưa thực hiện | G9: EP | H9: M | I9: M | J9: Quân
A10: REG-08 | B10: Mật khẩu ngắn hơn tối thiểu 1 ký tự (*) | C10: Độ dài mật khẩu = min−1 (min xác nhận trên site ở Ngày 1) | D10: Báo lỗi độ dài mật khẩu | E10: Chưa thực hiện | G10: BVA | H10: H | I10: A | J10: Quân
A11: REG-09 | B11: Mật khẩu đúng bằng độ dài tối thiểu và min+1 (*) | C11: Độ dài mật khẩu = min; min+1 | D11: Chấp nhận mật khẩu, đăng ký được | E11: Chưa thực hiện | G11: BVA | H11: M | I11: A | J11: Quân
A12: REG-10 | B12: Mật khẩu xác nhận không khớp | C12: mật khẩu: Test@12345 xác nhận: Test@54321 (nếu form có trường này) | D12: Báo lỗi mật khẩu xác nhận không khớp | E12: Chưa thực hiện | G12: EP | H12: M | I12: A | J12: Quân
A13: REG-11 | B13: Họ tên có số, ký tự đặc biệt, khoảng trắng đầu-cuối, tiếng Việt có dấu | C13: họ tên: Nguyen123 | @@@ | " An " | Trần Thị Ánh Tuyết | D13: Hành vi nhất quán: chấp nhận hoặc báo lỗi rõ ràng; dấu hiển thị đúng | E13: Chưa thực hiện | G13: ET | H13: L | I13: M | J13: Quân
A14: REG-12 | B14: Họ tên/email dài vượt giới hạn (*) | C14: Chuỗi dài max+1 ký tự ở họ tên và email | D14: Báo lỗi hoặc cắt chuỗi, không vỡ giao diện | E14: Chưa thực hiện | G14: BVA | H14: L | I14: M | J14: Quân
... A16: REG-14 | B16: Nút ẩn/hiện mật khẩu và thông báo lỗi tiếng Việt | C16: Nhập mật khẩu → bấm biểu tượng mắt; kích hoạt một số lỗi validation | D16: Ẩn/hiện đúng; thông báo lỗi rõ ràng, dễ hiểu | E16: Chưa thực hiện | G16: UC | H16: L | I16: M | J16: Quân
A17: 2. Chức năng đăng nhập, đăng xuất, quên mật khẩu (Bảng 4.8)
A18: LOG-01 | B18: Đăng nhập hợp lệ bằng Email | C18: email: tài khoản test của Quân mật khẩu: đúng | D18: Đăng nhập thành công, hiển thị tên/trang cá nhân | E18: Chưa thực hiện | G18: EP | H18: H | I18: A+M | J18: Quân
A19: LOG-02 | B19: Đăng nhập hợp lệ bằng SĐT | C19: SĐT: tài khoản test của Quân mật khẩu: đúng | D19: Đăng nhập thành công | E19: Chưa thực hiện | G19: EP | H19: H | I19: A+M | J19: Quân
A20: LOG-03 | B20: Đúng email, sai mật khẩu | C20: email: đúng mật khẩu: Sai@99999 | D20: Báo lỗi thông tin đăng nhập, không vào hệ thống | E20: Chưa thực hiện | G20: EP | H20: H | I20: A | J20: Quân
A21: LOG-04 | B21: Email/SĐT không tồn tại | C21: email: khongtontai_nhom17@example.com / SĐT: 0900000000 | D21: Báo lỗi phù hợp, không tiết lộ quá mức | E21: Chưa thực hiện | G21: EP | H21: H | I21: A | J21: Quân
A22: LOG-05 | B22: Để trống cả email/SĐT và mật khẩu | C22: email/SĐT: [trống]; mật khẩu: [trống] | D22: Báo lỗi bắt buộc nhập | E22: Chưa thực hiện | G22: EP | H22: H | I22: A | J22: Quân
A23: LOG-06 | B23: Chỉ để trống mật khẩu | C23: email: đúng; mật khẩu: [trống] | D23: Báo lỗi tại trường mật khẩu | E23: Chưa thực hiện | G23: EP | H23: M | I23: A | J23: Quân
A24: LOG-07 | B24: Chỉ để trống email/SĐT | C24: email/SĐT: [trống]; mật khẩu: đúng | D24: Báo lỗi tại trường định danh | E24: Chưa thực hiện | G24: EP | H24: M | I24: A | J24: Quân
A25: LOG-08 | B25: Email sai định dạng; khoảng trắng đầu/cuối | C25: email: abc | abc@ | " email_hop_le " (parametrize) | D25: Báo lỗi định dạng hoặc tự trim và đăng nhập được | E25: Chưa thực hiện | G25: EP, ET | H25: M | I25: A | J25: Quân
A26: LOG-09 | B26: Phân biệt hoa/thường của email và mật khẩu | C26: email: viết HOA toàn bộ; mật khẩu: đổi hoa/thường 1 ký tự | D26: Email không phân biệt hoa/thường; mật khẩu có phân biệt | E26: Chưa thực hiện | G26: ET | H26: L | I26: M | J26: Quân
A27: LOG-10 | B27: Nhập sai mật khẩu liên tiếp 5 lần | C27: Dùng tài khoản dành riêng cho LOG-10; sai mật khẩu 5 lần | D27: Ghi nhận cơ chế của site: khóa tạm / CAPTCHA / chỉ báo lỗi | E27: Chưa thực hiện | G27: ST | H27: M | I27: M | J27: Quân
A28: LOG-11 | B28: Ẩn/hiện mật khẩu | C28: Nhập mật khẩu → bấm biểu tượng mắt | D28: Hiển thị/ẩn đúng | E28: Chưa thực hiện | G28: UC | H28: L | I28: M | J28: Quân
A29: LOG-12 | B29: Đăng xuất | C29: Đăng nhập → bấm Đăng xuất → bấm nút Back của trình duyệt | D29: Về trạng thái chưa đăng nhập; Back không vào lại được trang cá nhân | E29: Chưa thực hiện | G29: ST | H29: H | I29: A+M | J29: Quân
... A31: LOG-14 | B31: Quên mật khẩu | C31: email: hợp lệ (email của nhóm) | không tồn tại | [trống] | D31: Thông báo gửi hướng dẫn / báo lỗi tương ứng (chỉ dùng email của nhóm) | E31: Chưa thực hiện | G31: EP | H31: L | I31: M | J31: Quân
A32: 3. Chức năng tìm kiếm sản phẩm (Bảng 4.9)
A33: SRC-01 | B33: Tìm theo từ khóa tên sản phẩm | C33: từ khóa: áo thun | D33: Danh sách sản phẩm liên quan; tên chứa/liên quan từ khóa | E33: Chưa thực hiện | G33: EP | H33: H | I33: A | J33: Lâm
A34: SRC-02 | B34: Tìm với nhiều từ khóa khác nhau | C34: từ khóa: quần short | áo polo | váy (parametrize) | D34: Kết quả phù hợp với từng từ khóa | E34: Chưa thực hiện | G34: EP | H34: H | I34: A | J34: Lâm
A35: SRC-03 | B35: Tìm không dấu so với có dấu | C35: từ khóa: ao thun so với áo thun | D35: Kết quả tương đương (hoặc ghi nhận khác biệt) | E35: Chưa thực hiện | G35: ET | H35: M | I35: A | J35: Lâm
A36: SRC-04 | B36: Tìm với chữ HOA/thường/lẫn lộn | C36: từ khóa: ÁO THUN | Áo Thun | áo thun | D36: Kết quả giống nhau | E36: Chưa thực hiện | G36: EP | H36: M | I36: A | J36: Lâm
A37: SRC-05 | B37: Từ khóa không tồn tại | C37: từ khóa: asdfghjk | D37: Thông báo "không tìm thấy", trang không lỗi | E37: Chưa thực hiện | G37: EP | H37: H | I37: A | J37: Lâm
A38: SRC-06 | B38: Để trống ô tìm kiếm rồi tìm | C38: từ khóa: [trống] | D38: Không lỗi; không điều hướng sai | E38: Chưa thực hiện | G38: EP | H38: M | I38: A | J38: Lâm
A39: SRC-07 | B39: Chỉ nhập khoảng trắng | C39: từ khóa: " " | D39: Xử lý như trống | E39: Chưa thực hiện | G39: EP | H39: L | I39: A | J39: Lâm
A40: SRC-08 | B40: Ký tự đặc biệt, số, emoji | C40: từ khóa: 12345 | <>"'% | 😀 (parametrize) | D40: Không vỡ giao diện, không lỗi 5xx (chỉ kiểm tra tính ổn định, không phải kiểm thử bảo mật) | E40: Chưa thực hiện | G40: ET | H40: M | I40: A | J40: Lâm
A41: SRC-09 | B41: Tìm theo màu / size / mã sản phẩm | C41: từ khóa: áo thun đen | size L | mã SP có sẵn | D41: Kết quả phản ánh thuộc tính, hoặc ghi nhận site không hỗ trợ | E41: Chưa thực hiện | G41: EP | H41: H | I41: A+M | J41: Lâm
A42: SRC-10 | B42: Hiển thị kết quả: ảnh, tên, giá, nhãn | C42: Thực hiện tìm kiếm bất kỳ có kết quả | D42: Đủ ảnh, tên, giá (định dạng VNĐ), nhãn New/Best Seller/Sale | E42: Chưa thực hiện | G42: UC | H42: H | I42: A+M | J42: Lâm
...

Sheet Tong_hop
A1: TỔNG HỢP BỘ TEST CASE – KIỂM THỬ WEBSITE COOLMATE (NHÓM 17)
A3: Chỉ số | B3: Giá trị | D3: Tiến độ | E3: Giá trị
A4: Tổng số test case | B4: =B21 -> 120 | D4: Chưa thực hiện | E4: =COUNTIF(Bang_Thiet_Ke_Ca_Kiem_Thu!E2:E132,"Chưa thực hiện") -> 120
A5: Đã ghi Pass | B5: =COUNTIF(Bang_Thiet_Ke_Ca_Kiem_Thu!F2:F132,"P") -> 0 | D5: Đã có kết quả (P/F/B) | E5: =B5+B6+B7 -> 0
A6: Đã ghi Fail | B6: =COUNTIF(Bang_Thiet_Ke_Ca_Kiem_Thu!F2:F132,"F") -> 0 | D6: Tỷ lệ Pass (Pass / (Pass+Fail)) | E6: =IF(B5+B6=0,"-",B5/(B5+B6)) -> -
A7: Blocked | B7: =COUNTIF(Bang_Thiet_Ke_Ca_Kiem_Thu!F2:F132,"B") -> 0
A9: Nhóm chức năng | B9: Số test case | C9: Pass | D9: Fail | E9: Blocked | F9: Tỷ lệ Pass | G9: Auto (A, A+M) | H9: Manual (M) | I9: Ưu tiên cao (H) | J9: Phụ trách
A10: Đăng ký | B10: =COUNTA(Bang_Thiet_Ke_Ca_Kiem_Thu!A3:A16) -> 14 | C10: =COUNTIF(Bang_Thiet_Ke_Ca_Kiem_Thu!F3:F16,"P") -> 0 | D10: =COUNTIF(Bang_Thiet_Ke_Ca_Kiem_Thu!F3:F16,"F") -> 0 | E10: =COUNTIF(Bang_Thiet_Ke_Ca_Kiem_Thu!F3:F16,"B") -> 0 | F10: =IF(C10+D10=0,"-",C10/(C10+D10)) -> - | G10: =COUNTIF(Bang_Thiet_Ke_Ca_Kiem_Thu!I3:I16,"A")+COUNTIF(Bang_Thiet_Ke_Ca_Kiem_Thu!I3:I16,"A+M") -> 9 | H10: =COUNTIF(Bang_Thiet_Ke_Ca_Kiem_Thu!I3:I16,"M") -> 5 | I10: =COUNTIF(Bang_Thiet_Ke_Ca_Kiem_Thu!H3:H16,"H") -> 7 | J10: TV2
A11: Đăng nhập / đăng xuất / quên mật khẩu | B11: =COUNTA(Bang_Thiet_Ke_Ca_Kiem_Thu!A18:A31) -> 14 | C11: =COUNTIF(Bang_Thiet_Ke_Ca_Kiem_Thu!F18:F31,"P") -> 0 | D11: =COUNTIF(Bang_Thiet_Ke_Ca_Kiem_Thu!F18:F31,"F") -> 0 | E11: =COUNTIF(Bang_Thiet_Ke_Ca_Kiem_Thu!F18:F31,"B") -> 0 | F11: =IF(C11+D11=0,"-",C11/(C11+D11)) -> - | G11: =COUNTIF(Bang_Thiet_Ke_Ca_Kiem_Thu!I18:I31,"A")+COUNTIF(Bang_Thiet_Ke_Ca_Kiem_Thu!I18:I31,"A+M") -> 9 | H11: =COUNTIF(Bang_Thiet_Ke_Ca_Kiem_Thu!I18:I31,"M") -> 5 | I11: =COUNTIF(Bang_Thiet_Ke_Ca_Kiem_Thu!H18:H31,"H") -> 6 | J11: TV2
A12: Tìm kiếm | B12: =COUNTA(Bang_Thiet_Ke_Ca_Kiem_Thu!A33:A45) -> 13 | C12: =COUNTIF(Bang_Thiet_Ke_Ca_Kiem_Thu!F33:F45,"P") -> 0 | D12: =COUNTIF(Bang_Thiet_Ke_Ca_Kiem_Thu!F33:F45,"F") -> 0 | E12: =COUNTIF(Bang_Thiet_Ke_Ca_Kiem_Thu!F33:F45,"B") -> 0 | F12: =IF(C12+D12=0,"-",C12/(C12+D12)) -> - | G12: =COUNTIF(Bang_Thiet_Ke_Ca_Kiem_Thu!I33:I45,"A")+COUNTIF(Bang_Thiet_Ke_Ca_Kiem_Thu!I33:I45,"A+M") -> 12 | H12: =COUNTIF(Bang_Thiet_Ke_Ca_Kiem_Thu!I33:I45,"M") -> 1 | I12: =COUNTIF(Bang_Thiet_Ke_Ca_Kiem_Thu!H33:H45,"H") -> 6 | J12: TV3
A13: Lọc / sắp xếp | B13: =COUNTA(Bang_Thiet_Ke_Ca_Kiem_Thu!A47:A58) -> 12 | C13: =COUNTIF(Bang_Thiet_Ke_Ca_Kiem_Thu!F47:F58,"P") -> 0 | D13: =COUNTIF(Bang_Thiet_Ke_Ca_Kiem_Thu!F47:F58,"F") -> 0 | E13: =COUNTIF(Bang_Thiet_Ke_Ca_Kiem_Thu!F47:F58,"B") -> 0 | F13: =IF(C13+D13=0,"-",C13/(C13+D13)) -> - | G13: =COUNTIF(Bang_Thiet_Ke_Ca_Kiem_Thu!I47:I58,"A")+COUNTIF(Bang_Thiet_Ke_Ca_Kiem_Thu!I47:I58,"A+M") -> 10 | H13: =COUNTIF(Bang_Thiet_Ke_Ca_Kiem_Thu!I47:I58,"M") -> 2 | I13: =COUNTIF(Bang_Thiet_Ke_Ca_Kiem_Thu!H47:H58,"H") -> 5 | J13: TV3
A14: Chi tiết sản phẩm | B14: =COUNTA(Bang_Thiet_Ke_Ca_Kiem_Thu!A60:A69) -> 10 | C14: =COUNTIF(Bang_Thiet_Ke_Ca_Kiem_Thu!F60:F69,"P") -> 0 | D14: =COUNTIF(Bang_Thiet_Ke_Ca_Kiem_Thu!F60:F69,"F") -> 0 | E14: =COUNTIF(Bang_Thiet_Ke_Ca_Kiem_Thu!F60:F69,"B") -> 0 | F14: =IF(C14+D14=0,"-",C14/(C14+D14)) -> - | G14: =COUNTIF(Bang_Thiet_Ke_Ca_Kiem_Thu!I60:I69,"A")+COUNTIF(Bang_Thiet_Ke_Ca_Kiem_Thu!I60:I69,"A+M") -> 7 | H14: =COUNTIF(Bang_Thiet_Ke_Ca_Kiem_Thu!I60:I69,"M") -> 3 | I14: =COUNTIF(Bang_Thiet_Ke_Ca_Kiem_Thu!H60:H69,"H") -> 6 | J14: TV3
A15: Giao diện & tương thích | B15: =COUNTA(Bang_Thiet_Ke_Ca_Kiem_Thu!A71:A77) -> 7 | C15: =COUNTIF(Bang_Thiet_Ke_Ca_Kiem_Thu!F71:F77,"P") -> 0 | D15: =COUNTIF(Bang_Thiet_Ke_Ca_Kiem_Thu!F71:F77,"F") -> 0 | E15: =COUNTIF(Bang_Thiet_Ke_Ca_Kiem_Thu!F71:F77,"B") -> 0 | F15: =IF(C15+D15=0,"-",C15/(C15+D15)) -> - | G15: =COUNTIF(Bang_Thiet_Ke_Ca_Kiem_Thu!I71:I77,"A")+COUNTIF(Bang_Thiet_Ke_Ca_Kiem_Thu!I71:I77,"A+M") -> 3 | H15: =COUNTIF(Bang_Thiet_Ke_Ca_Kiem_Thu!I71:I77,"M") -> 4 | I15: =COUNTIF(Bang_Thiet_Ke_Ca_Kiem_Thu!H71:H77,"H") -> 1 | J15: TV3
A16: Giỏ hàng | B16: =COUNTA(Bang_Thiet_Ke_Ca_Kiem_Thu!A79:A90) -> 12 | C16: =COUNTIF(Bang_Thiet_Ke_Ca_Kiem_Thu!F79:F90,"P") -> 0 | D16: =COUNTIF(Bang_Thiet_Ke_Ca_Kiem_Thu!F79:F90,"F") -> 0 | E16: =COUNTIF(Bang_Thiet_Ke_Ca_Kiem_Thu!F79:F90,"B") -> 0 | F16: =IF(C16+D16=0,"-",C16/(C16+D16)) -> - | G16: =COUNTIF(Bang_Thiet_Ke_Ca_Kiem_Thu!I79:I90,"A")+COUNTIF(Bang_Thiet_Ke_Ca_Kiem_Thu!I79:I90,"A+M") -> 10 | H16: =COUNTIF(Bang_Thiet_Ke_Ca_Kiem_Thu!I79:I90,"M") -> 2 | I16: =COUNTIF(Bang_Thiet_Ke_Ca_Kiem_Thu!H79:H90,"H") -> 7 | J16: TV4
A17: Mã giảm giá | B17: =COUNTA(Bang_Thiet_Ke_Ca_Kiem_Thu!A92:A101) -> 10 | C17: =COUNTIF(Bang_Thiet_Ke_Ca_Kiem_Thu!F92:F101,"P") -> 0 | D17: =COUNTIF(Bang_Thiet_Ke_Ca_Kiem_Thu!F92:F101,"F") -> 0 | E17: =COUNTIF(Bang_Thiet_Ke_Ca_Kiem_Thu!F92:F101,"B") -> 0 | F17: =IF(C17+D17=0,"-",C17/(C17+D17)) -> - | G17: =COUNTIF(Bang_Thiet_Ke_Ca_Kiem_Thu!I92:I101,"A")+COUNTIF(Bang_Thiet_Ke_Ca_Kiem_Thu!I92:I101,"A+M") -> 8 | H17: =COUNTIF(Bang_Thiet_Ke_Ca_Kiem_Thu!I92:I101,"M") -> 2 | I17: =COUNTIF(Bang_Thiet_Ke_Ca_Kiem_Thu!H92:H101,"H") -> 5 | J17: TV4
A18: Đặt hàng & thanh toán | B18: =COUNTA(Bang_Thiet_Ke_Ca_Kiem_Thu!A103:A116) -> 14 | C18: =COUNTIF(Bang_Thiet_Ke_Ca_Kiem_Thu!F103:F116,"P") -> 0 | D18: =COUNTIF(Bang_Thiet_Ke_Ca_Kiem_Thu!F103:F116,"F") -> 0 | E18: =COUNTIF(Bang_Thiet_Ke_Ca_Kiem_Thu!F103:F116,"B") -> 0 | F18: =IF(C18+D18=0,"-",C18/(C18+D18)) -> - | G18: =COUNTIF(Bang_Thiet_Ke_Ca_Kiem_Thu!I103:I116,"A")+COUNTIF(Bang_Thiet_Ke_Ca_Kiem_Thu!I103:I116,"A+M") -> 11 | H18: =COUNTIF(Bang_Thiet_Ke_Ca_Kiem_Thu!I103:I116,"M") -> 3 | I18: =COUNTIF(Bang_Thiet_Ke_Ca_Kiem_Thu!H103:H116,"H") -> 8 | J18: TV4
A19: Quản lý tài khoản | B19: =COUNTA(Bang_Thiet_Ke_Ca_Kiem_Thu!A118:A128) -> 11 | C19: =COUNTIF(Bang_Thiet_Ke_Ca_Kiem_Thu!F118:F128,"P") -> 0 | D19: =COUNTIF(Bang_Thiet_Ke_Ca_Kiem_Thu!F118:F128,"F") -> 0 | E19: =COUNTIF(Bang_Thiet_Ke_Ca_Kiem_Thu!F118:F128,"B") -> 0 | F19: =IF(C19+D19=0,"-",C19/(C19+D19)) -> - | G19: =COUNTIF(Bang_Thiet_Ke_Ca_Kiem_Thu!I118:I128,"A")+COUNTIF(Bang_Thiet_Ke_Ca_Kiem_Thu!I118:I128,"A+M") -> 10 | H19: =COUNTIF(Bang_Thiet_Ke_Ca_Kiem_Thu!I118:I128,"M") -> 1 | I19: =COUNTIF(Bang_Thiet_Ke_Ca_Kiem_Thu!H118:H128,"H") -> 6 | J19: TV1
A20: Lịch sử đơn hàng | B20: =COUNTA(Bang_Thiet_Ke_Ca_Kiem_Thu!A130:A132) -> 3 | C20: =COUNTIF(Bang_Thiet_Ke_Ca_Kiem_Thu!F130:F132,"P") -> 0 | D20: =COUNTIF(Bang_Thiet_Ke_Ca_Kiem_Thu!F130:F132,"F") -> 0 | E20: =COUNTIF(Bang_Thiet_Ke_Ca_Kiem_Thu!F130:F132,"B") -> 0 | F20: =IF(C20+D20=0,"-",C20/(C20+D20)) -> - | G20: =COUNTIF(Bang_Thiet_Ke_Ca_Kiem_Thu!I130:I132,"A")+COUNTIF(Bang_Thiet_Ke_Ca_Kiem_Thu!I130:I132,"A+M") -> 0 | H20: =COUNTIF(Bang_Thiet_Ke_Ca_Kiem_Thu!I130:I132,"M") -> 3 | I20: =COUNTIF(Bang_Thiet_Ke_Ca_Kiem_Thu!H130:H132,"H") -> 0 | J20: TV1
A21: Tổng | B21: =SUM(B10:B20) -> 120 | C21: =SUM(C10:C20) -> 0 | D21: =SUM(D10:D20) -> 0 | E21: =SUM(E10:E20) -> 0 | F21: =IF(C21+D21=0,"-",C21/(C21+D21)) -> - | G21: =SUM(G10:G20) -> 89 | H21: =SUM(H10:H20) -> 31 | I21: =SUM(I10:I20) -> 57
A23: Ghi chú: Cột Pass/Fail được để trống vì chưa chạy test (Actual Results = "Chưa thực hiện"). Chỉ điền P / F / B sau khi chạy thật; Blocked (B) không tính vào mẫu số của tỷ lệ Pass. Các giá trị đánh dấu (*) cần xác nhận lại trên website thật trước khi đóng băng (Gate 1).

Sheet Quy_uoc
A1: QUY ƯỚC SỬ DỤNG FILE
A2: Pass/Fail | B2: P = Pass · F = Fail (lỗi thật của website) · B = Blocked (CAPTCHA, hết hàng, site bảo trì…). Lỗi do script/locator KHÔNG tính là F của website.
A3: Actual Results | B3: Ghi kết quả quan sát thực tế khi chạy; thay chữ "Chưa thực hiện" sau khi chạy.
A4: Kỹ thuật (KT) | B4: EP = Phân vùng tương đương · BVA = Giá trị biên · DT = Bảng quyết định · ST = Chuyển trạng thái · ET = Đoán lỗi · UC = Dựa trên use case
A5: Ưu tiên | B5: H = Cao · M = Trung bình · L = Thấp
A6: Loại | B6: A = Tự động (Selenium) · M = Thủ công · A+M = chạy cả hai
A7: Dấu (*) | B7: Giá trị biên / quy tắc phải xác nhận lại trên website thật ở Ngày 1–2 trước khi đóng băng test case.
A8: Test Data | B8: Email/SĐT dùng tài khoản của nhóm (alias/email tạm); thay các giá trị mẫu bằng dữ liệu thật của nhóm. Không commit mật khẩu thật lên GitHub.
A9: An toàn (website thật) | B9: Đặt hàng: chỉ COD, dừng trước bước xác nhận cuối (trừ ORD-14: tối đa 1–2 đơn rồi hủy ngay). Voucher: chỉ dùng mã công khai. Không thanh toán online thật. Gặp CAPTCHA/OTP → chuyển Manual hoặc Blocked.
A10: Quy tắc đặt tên | B10: Tên hàm pytest = TC ID, ví dụ def test_REG_01_register_valid để results.csv khớp 1–1 với file này.
A11: Cột bổ sung | B11: Cột A–F giữ nguyên theo template; cột G–M bổ sung để theo dõi (kỹ thuật, ưu tiên, loại, người phụ trách, ngày chạy, Bug ID, evidence).
